Workbook

Sheet Planilha1
B10: CONFIGURAÇÕES
B11: Sálario | D11: 3500
B12: Rendimento Carteira | D12: 0.008
B13: Valor mínimo para Investir | D13: =D11*20% -> 700
B15: INVESTIMENTO MENSAL
B16: Quanto Investir por Mês? | D16: 700
B17: Por quantos Anos? | D17: 20
B18: Taxa de Rendimento Mensal? | D18: 0.01079
B19: Patrimônio Acumulado? | D19: =FV(D18,D17*12,D16*-1) -> 787638.88
B20: Dividendos Mensais? | D20: =D19*1% -> 7876.3888
B22: CENÁRIOS | D22: DIVIDENDOS
A23: 2 | B23: Quantos em 2 anos ? | C23: =FV(D$18,$A23*12,$D$16*-1) -> 19059.339 | D23: =C23*1% -> 190.59339
A24: 5 | B24: Quantos em 5 anos ? | C24: =FV(D$18,$A24*12,$D$16*-1) -> 58643.84 | D24: =C24*1% -> 586.4384
A25: 10 | B25: Quantos em 10 anos ? | C25: =FV(D$18,$A25*12,$D$16*-1) -> 170298.95 | D25: =C25*1% -> 1702.9895
A26: 20 | B26: Quantos em 20 anos ? | C26: =FV(D$18,$A26*12,$D$16*-1) -> 787638.88 | D26: =C26*1% -> 7876.3888
A27: 30 | B27: Quantos em 30 anos ? | C27: =FV(D$18,$A27*12,$D$16*-1) -> 3025518.8 | D27: =C27*1% -> 30255.188
B30: PERFIL | C30: MODERADO
B31: VALOR A SER INVESTIDO POR MÊS | C31: 700
B33: TIPO DE INVESTIMENTO | C33: PERCENTUAL SUGERIDO | D33: VALORES | E33: VALORES GRAFICO
B34: =IFERROR(INDEX(Planilha2!$C$2:$C$28,MATCH(ROWS($B$34:B34),Planilha2!$E$2:$E$28,0)),"") -> CDB com liquidez diária | C34: =IF(B34="","",INDEX(Planilha2!$D$2:$D$28,MATCH(ROWS($B$34:B34),Planilha2!$E$2:$E$28,0))) -> 0.1 | D34: =IF(B34="","",C34*$C$31) -> 70 | E34: =IF(D34=0,NA(),D34) -> 70
B35: =IFERROR(INDEX(Planilha2!$C$2:$C$28,MATCH(ROWS($B$34:B35),Planilha2!$E$2:$E$28,0)),"") -> LCI / LCA | C35: =IF(B35="","",INDEX(Planilha2!$D$2:$D$28,MATCH(ROWS($B$34:B35),Planilha2!$E$2:$E$28,0))) -> 0.1 | D35: =IF(B35="","",C35*$C$31) -> 70 | E35: =IF(D35=0,NA(),D35) -> 70
B36: =IFERROR(INDEX(Planilha2!$C$2:$C$28,MATCH(ROWS($B$34:B36),Planilha2!$E$2:$E$28,0)),"") -> Tesouro Selic | C36: =IF(B36="","",INDEX(Planilha2!$D$2:$D$28,MATCH(ROWS($B$34:B36),Planilha2!$E$2:$E$28,0))) -> 0.1 | D36: =IF(B36="","",C36*$C$31) -> 70 | E36: =IF(D36=0,NA(),D36) -> 70
B37: =IFERROR(INDEX(Planilha2!$C$2:$C$28,MATCH(ROWS($B$34:B37),Planilha2!$E$2:$E$28,0)),"") -> Tesouro IPCA+ | C37: =IF(B37="","",INDEX(Planilha2!$D$2:$D$28,MATCH(ROWS($B$34:B37),Planilha2!$E$2:$E$28,0))) -> 0.15 | D37: =IF(B37="","",C37*$C$31) -> 105 | E37: =IF(D37=0,NA(),D37) -> 105
B38: =IFERROR(INDEX(Planilha2!$C$2:$C$28,MATCH(ROWS($B$34:B38),Planilha2!$E$2:$E$28,0)),"") -> Tesouro Prefixado | C38: =IF(B38="","",INDEX(Planilha2!$D$2:$D$28,MATCH(ROWS($B$34:B38),Planilha2!$E$2:$E$28,0))) -> 0.05 | D38: =IF(B38="","",C38*$C$31) -> 35 | E38: =IF(D38=0,NA(),D38) -> 35
B39: =IFERROR(INDEX(Planilha2!$C$2:$C$28,MATCH(ROWS($B$34:B39),Planilha2!$E$2:$E$28,0)),"") -> FIIs | C39: =IF(B39="","",INDEX(Planilha2!$D$2:$D$28,MATCH(ROWS($B$34:B39),Planilha2!$E$2:$E$28,0))) -> 0.08 | D39: =IF(B39="","",C39*$C$31) -> 56 | E39: =IF(D39=0,NA(),D39) -> 56
B40: =IFERROR(INDEX(Planilha2!$C$2:$C$28,MATCH(ROWS($B$34:B40),Planilha2!$E$2:$E$28,0)),"") -> FIAGRO | C40: =IF(B40="","",INDEX(Planilha2!$D$2:$D$28,MATCH(ROWS($B$34:B40),Planilha2!$E$2:$E$28,0))) -> 0.04 | D40: =IF(B40="","",C40*$C$31) -> 28 | E40: =IF(D40=0,NA(),D40) -> 28
B41: =IFERROR(INDEX(Planilha2!$C$2:$C$28,MATCH(ROWS($B$34:B41),Planilha2!$E$2:$E$28,0)),"") -> Ações por setor | C41: =IF(B41="","",INDEX(Planilha2!$D$2:$D$28,MATCH(ROWS($B$34:B41),Planilha2!$E$2:$E$28,0))) -> 0.12 | D41: =IF(B41="","",C41*$C$31) -> 84 | E41: =IF(D41=0,NA(),D41) -> 84
B42: =IFERROR(INDEX(Planilha2!$C$2:$C$28,MATCH(ROWS($B$34:B42),Planilha2!$E$2:$E$28,0)),"") -> BDRs | C42: =IF(B42="","",INDEX(Planilha2!$D$2:$D$28,MATCH(ROWS($B$34:B42),Planilha2!$E$2:$E$28,0))) -> 0.05 | D42: =IF(B42="","",C42*$C$31) -> 35 | E42: =IF(D42=0,NA(),D42) -> 35
B43: =IFERROR(INDEX(Planilha2!$C$2:$C$28,MATCH(ROWS($B$34:B43),Planilha2!$E$2:$E$28,0)),"") -> ETFs internacionais | C43: =IF(B43="","",INDEX(Planilha2!$D$2:$D$28,MATCH(ROWS($B$34:B43),Planilha2!$E$2:$E$28,0))) -> 0.1 | D43: =IF(B43="","",C43*$C$31) -> 70 | E43: =IF(D43=0,NA(),D43) -> 70
B44: =IFERROR(INDEX(Planilha2!$C$2:$C$28,MATCH(ROWS($B$34:B44),Planilha2!$E$2:$E$28,0)),"") -> Ouro | C44: =IF(B44="","",INDEX(Planilha2!$D$2:$D$28,MATCH(ROWS($B$34:B44),Planilha2!$E$2:$E$28,0))) -> 0.03 | D44: =IF(B44="","",C44*$C$31) -> 21 | E44: =IF(D44=0,NA(),D44) -> 21
B45: =IFERROR(INDEX(Planilha2!$C$2:$C$28,MATCH(ROWS($B$34:B45),Planilha2!$E$2:$E$28,0)),"") -> Fundos DI / renda fixa | C45: =IF(B45="","",INDEX(Planilha2!$D$2:$D$28,MATCH(ROWS($B$34:B45),Planilha2!$E$2:$E$28,0))) -> 0.08 | D45: =IF(B45="","",C45*$C$31) -> 56 | E45: =IF(D45=0,NA(),D45) -> 56
B46: =IFERROR(INDEX(Planilha2!$C$2:$C$28,MATCH(ROWS($B$34:B46),Planilha2!$E$2:$E$28,0)),"") | C46: =IF(B46="","",INDEX(Planilha2!$D$2:$D$28,MATCH(ROWS($B$34:B46),Planilha2!$E$2:$E$28,0))) | D46: =IF(B46="","",C46*$C$31) | E46: =IF(D46=0,NA(),D46)
B47: =IFERROR(INDEX(Planilha2!$C$2:$C$28,MATCH(ROWS($B$34:B47),Planilha2!$E$2:$E$28,0)),"") | C47: =IF(B47="","",INDEX(Planilha2!$D$2:$D$28,MATCH(ROWS($B$34:B47),Planilha2!$E$2:$E$28,0))) | D47: =IF(B47="","",C47*$C$31)
B48: =IFERROR(INDEX(Planilha2!$C$2:$C$28,MATCH(ROWS($B$34:B48),Planilha2!$E$2:$E$28,0)),"") | C48: =IF(B48="","",INDEX(Planilha2!$D$2:$D$28,MATCH(ROWS($B$34:B48),Planilha2!$E$2:$E$28,0))) | D48: =IF(B48="","",C48*$C$31)
B49: =IFERROR(INDEX(Planilha2!$C$2:$C$28,MATCH(ROWS($B$34:B49),Planilha2!$E$2:$E$28,0)),"") | C49: =IF(B49="","",INDEX(Planilha2!$D$2:$D$28,MATCH(ROWS($B$34:B49),Planilha2!$E$2:$E$28,0))) | D49: =IF(B49="","",C49*$C$31)
B50: =IFERROR(INDEX(Planilha2!$C$2:$C$28,MATCH(ROWS($B$34:B50),Planilha2!$E$2:$E$28,0)),"") | C50: =IF(B50="","",INDEX(Planilha2!$D$2:$D$28,MATCH(ROWS($B$34:B50),Planilha2!$E$2:$E$28,0))) | D50: =IF(B50="","",C50*$C$31)
B51: =IFERROR(INDEX(Planilha2!$C$2:$C$28,MATCH(ROWS($B$34:B51),Planilha2!$E$2:$E$28,0)),"") | C51: =IF(B51="","",INDEX(Planilha2!$D$2:$D$28,MATCH(ROWS($B$34:B51),Planilha2!$E$2:$E$28,0))) | D51: =IF(B51="","",C51*$C$31)
B52: =IFERROR(INDEX(Planilha2!$C$2:$C$28,MATCH(ROWS($B$34:B52),Planilha2!$E$2:$E$28,0)),"") | C52: =IF(B52="","",INDEX(Planilha2!$D$2:$D$28,MATCH(ROWS($B$34:B52),Planilha2!$E$2:$E$28,0))) | D52: =IF(B52="","",C52*$C$31)
B53: =IFERROR(INDEX(Planilha2!$C$2:$C$28,MATCH(ROWS($B$34:B53),Planilha2!$E$2:$E$28,0)),"") | C53: =IF(B53="","",INDEX(Planilha2!$D$2:$D$28,MATCH(ROWS($B$34:B53),Planilha2!$E$2:$E$28,0))) | D53: =IF(B53="","",C53*$C$31)
B54: =IFERROR(INDEX(Planilha2!$C$2:$C$28,MATCH(ROWS($B$34:B54),Planilha2!$E$2:$E$28,0)),"") | C54: =IF(B54="","",INDEX(Planilha2!$D$2:$D$28,MATCH(ROWS($B$34:B54),Planilha2!$E$2:$E$28,0))) | D54: =IF(B54="","",C54*$C$31)
...

Sheet Planilha2
A1: chave | B1: PERFIL | C1: tipo de investimento | D1: % | E1: ORDEM_PERFIL
A2: =B2&"-"&C2 -> CONSERVADOR-Tesouro Selic | B2: CONSERVADOR | C2: Tesouro Selic | D2: 0.3 | E2: =IF(B2=Planilha1!$C$30,COUNTIF($B$2:B2,Planilha1!$C$30),"")
A3: =B3&"-"&C3 -> CONSERVADOR-CDB com liquidez diária | B3: CONSERVADOR | C3: CDB com liquidez diária | D3: 0.25 | E3: =IF(B3=Planilha1!$C$30,COUNTIF($B$2:B3,Planilha1!$C$30),"")
A4: =B4&"-"&C4 -> CONSERVADOR-LCI / LCA | B4: CONSERVADOR | C4: LCI / LCA | D4: 0.15 | E4: =IF(B4=Planilha1!$C$30,COUNTIF($B$2:B4,Planilha1!$C$30),"")
A5: =B5&"-"&C5 -> CONSERVADOR-Fundos DI / renda fixa | B5: CONSERVADOR | C5: Fundos DI / renda fixa | D5: 0.1 | E5: =IF(B5=Planilha1!$C$30,COUNTIF($B$2:B5,Planilha1!$C$30),"")
A6: =B6&"-"&C6 -> CONSERVADOR-Tesouro IPCA+ | B6: CONSERVADOR | C6: Tesouro IPCA+ | D6: 0.1 | E6: =IF(B6=Planilha1!$C$30,COUNTIF($B$2:B6,Planilha1!$C$30),"")
A7: =B7&"-"&C7 -> CONSERVADOR-Tesouro Prefixado | B7: CONSERVADOR | C7: Tesouro Prefixado | D7: 0.05 | E7: =IF(B7=Planilha1!$C$30,COUNTIF($B$2:B7,Planilha1!$C$30),"")
A8: =B8&"-"&C8 -> CONSERVADOR-Debêntures | B8: CONSERVADOR | C8: Debêntures | D8: 0.03 | E8: =IF(B8=Planilha1!$C$30,COUNTIF($B$2:B8,Planilha1!$C$30),"")
A9: =B9&"-"&C9 -> CONSERVADOR-Ouro | B9: CONSERVADOR | C9: Ouro | D9: 0.02 | E9: =IF(B9=Planilha1!$C$30,COUNTIF($B$2:B9,Planilha1!$C$30),"")
A10: =B10&"-"&C10 -> MODERADO-CDB com liquidez diária | B10: MODERADO | C10: CDB com liquidez diária | D10: 0.1 | E10: =IF(B10=Planilha1!$C$30,COUNTIF($B$2:B10,Planilha1!$C$30),"") -> 1
A11: =B11&"-"&C11 -> MODERADO-LCI / LCA | B11: MODERADO | C11: LCI / LCA | D11: 0.1 | E11: =IF(B11=Planilha1!$C$30,COUNTIF($B$2:B11,Planilha1!$C$30),"") -> 2
A12: =B12&"-"&C12 -> MODERADO-Tesouro Selic | B12: MODERADO | C12: Tesouro Selic | D12: 0.1 | E12: =IF(B12=Planilha1!$C$30,COUNTIF($B$2:B12,Planilha1!$C$30),"") -> 3
A13: =B13&"-"&C13 -> MODERADO-Tesouro IPCA+ | B13: MODERADO | C13: Tesouro IPCA+ | D13: 0.15 | E13: =IF(B13=Planilha1!$C$30,COUNTIF($B$2:B13,Planilha1!$C$30),"") -> 4
... A28: =B28&"-"&C28 -> ARROJADO-Opções / contratos futuros | B28: ARROJADO | C28: Opções / contratos futuros | D28: 0 | E28: =IF(B28=Planilha1!$C$30,COUNTIF($B$2:B28,Planilha1!$C$30),"")
